Workbook

Sheet Instructions
A1: Assessment Task: AI Manpower Allocation & Project Scheduling
A3: 1. Objective
A4: Design and develop a scalable, AI-enabled manpower allocation and project scheduling solution that can:
A5: Manage employees/resources
A6: Manage projects
A7: Manage stages/activities
A8: Allocate manpower to projects
A9: Calculate schedules based on dates and working calendars
A10: Identify manpower shortages
A11: Identify employee allocation conflicts
A12: Consider employee designation/skills when allocating
A13: Provide scheduling and reporting output
... A46: Using the supplied sample data and business rules as a reference, design and develop a scalable, AI-enabled manpower allocation and project scheduling solution with a proper, well-structured architecture covering the data layer, allocation logic, scheduling engine, validation/conflict checks, AI recommendations, and reporting output.

Sheet Stage-Designation Master
A1: Stage No. | B1: Production Stage | C1: Designation / Role | D1: Category | E1: Work Days | F1: Weekly Off | G1: Standard Shift (Hrs) | H1: Overtime Applicable | I1: Production Stage
A2: 1 | B2: Design | C2: Design Manager | D2: White Collar | E2: Mon–Fri | F2: Sat, Sun | G2: 8 | H2: No | I2: Design
A3: 1 | B3: Design | C3: Design Engineer | D3: White Collar | E3: Mon–Fri | F3: Sat, Sun | G3: 8 | H3: No | I3: Design
A4: 1 | B4: Design | C4: CAD Draftsman | D4: White Collar | E4: Mon–Fri | F4: Sat, Sun | G4: 8 | H4: No | I4: Design
A5: 2 | B5: Planning | C5: Planning Manager | D5: White Collar | E5: Mon–Fri | F5: Sat, Sun | G5: 8 | H5: No | I5: Planning
A6: 2 | B6: Planning | C6: Project Planner / Scheduler | D6: White Collar | E6: Mon–Fri | F6: Sat, Sun | G6: 8 | H6: No | I6: Planning
A7: 3 | B7: Procurement | C7: Procurement Manager | D7: White Collar | E7: Mon–Fri | F7: Sat, Sun | G7: 8 | H7: No | I7: Procurement
A8: 3 | B8: Procurement | C8: Procurement Officer | D8: White Collar | E8: Mon–Fri | F8: Sat, Sun | G8: 8 | H8: No | I8: Procurement
A9: 4 | B9: Sourcing | C9: Sourcing Manager | D9: White Collar | E9: Mon–Fri | F9: Sat, Sun | G9: 8 | H9: No | I9: Sourcing
A10: 4 | B10: Sourcing | C10: Vendor Development Executive | D10: White Collar | E10: Mon–Fri | F10: Sat, Sun | G10: 8 | H10: No | I10: Sourcing
A11: 5 | B11: Manufacturing | C11: Production Supervisor | D11: Blue Collar | E11: Mon–Sat | F11: Sun | G11: 8 | H11: Yes | I11: Manufacturing
A12: 5 | B12: Manufacturing | C12: Carpenter | D12: Blue Collar | E12: Mon–Sat | F12: Sun | G12: 8 | H12: Yes | I12: Manufacturing
A13: 5 | B13: Manufacturing | C13: Machine Operator (CNC/Edge Band) | D13: Blue Collar | E13: Mon–Sat | F13: Sun | G13: 8 | H13: Yes | I13: Manufacturing
... A23: 8 | B23: Shipping | C23: Driver | D23: Blue Collar | E23: Mon–Sat | F23: Sun | G23: 8 | H23: Yes | I23: Shipping

Sheet Employee Master (Sample)
A1: Employee ID | B1: Employee Name | C1: Designation | D1: Stage | E1: Category | F1: Work Days | G1: Weekly Off | H1: OT Eligible | I1: Skill Level | J1: Date of Joining | K1: Status
A2: EMP001 | B2: Ahmed Khan | C2: Design Manager | D2: Design | E2: White Collar | F2: Mon–Fri | G2: Sat, Sun | H2: No | I2: Mid | J2: 44635 | K2: Active
A3: EMP002 | B3: Ahmed Sharma | C3: Design Engineer | D3: Design | E3: White Collar | F3: Mon–Fri | G3: Sat, Sun | H3: No | I3: Mid | J3: 45056 | K3: Active
A4: EMP003 | B4: Ahmed Patel | C4: Design Engineer | D4: Design | E4: White Collar | F4: Mon–Fri | G4: Sat, Sun | H4: No | I4: Mid | J4: 44946 | K4: Active
A5: EMP004 | B5: Ahmed Malik | C5: Design Engineer | D5: Design | E5: White Collar | F5: Mon–Fri | G5: Sat, Sun | H5: No | I5: Mid | J5: 44635 | K5: Active
A6: EMP005 | B6: Ahmed Iyer | C6: CAD Draftsman | D6: Design | E6: White Collar | F6: Mon–Fri | G6: Sat, Sun | H6: No | I6: Senior | J6: 45828 | K6: Active
A7: EMP006 | B7: Ahmed Hussain | C7: CAD Draftsman | D7: Design | E7: White Collar | F7: Mon–Fri | G7: Sat, Sun | H7: No | I7: Mid | J7: 44571 | K7: Active
A8: EMP007 | B8: Ahmed Reddy | C8: CAD Draftsman | D8: Design | E8: White Collar | F8: Mon–Fri | G8: Sat, Sun | H8: No | I8: Mid | J8: 44635 | K8: Active
A9: EMP008 | B9: Ahmed Ansari | C9: Planning Manager | D9: Planning | E9: White Collar | F9: Mon–Fri | G9: Sat, Sun | H9: No | I9: Mid | J9: 44946 | K9: Active
A10: EMP009 | B10: Ahmed Nair | C10: Project Planner / Scheduler | D10: Planning | E10: White Collar | F10: Mon–Fri | G10: Sat, Sun | H10: No | I10: Mid | J10: 45672 | K10: Active
A11: EMP010 | B11: Ahmed Siddiqui | C11: Project Planner / Scheduler | D11: Planning | E11: White Collar | F11: Mon–Fri | G11: Sat, Sun | H11: No | I11: Senior | J11: 45672 | K11: Active
A12: EMP011 | B12: Ahmed Verma | C12: Procurement Manager | D12: Procurement | E12: White Collar | F12: Mon–Fri | G12: Sat, Sun | H12: No | I12: Senior | J12: 44946 | K12: Active
A13: EMP012 | B13: Ahmed Baig | C13: Procurement Officer | D13: Procurement | E13: White Collar | F13: Mon–Fri | G13: Sat, Sun | H13: No | I13: Senior | J13: 45828 | K13: Active
... A57: EMP056 | B57: Vinay | C57: Project Manager | D57: Manager | E57: White Collar | F57: Mon–Fri | G57: Sat, Sun | H57: No | I57: Mid | J57: 45689 | K57: Active

Sheet Project Master (Sample)
I1: PRODUCTION STAGES
A2: Project ID | B2: Project Name | C2: Client / Site | D2: Project Manager | E2: Location | F2: Priority | G2: Start Date | H2: Target End Date | I2: Design (Calendar Days) | J2: Planning (Calendar Days) | K2: Procurement (Calendar Days) | L2: Sourcing (Calendar Days) | M2: Manufacturing (Calendar Days) | N2: Quality Control (Calendar Days) | O2: Packing (Calendar Days) | P2: Shipping (Calendar Days) | Q2: Status
A3: PRJ001 | B3: Al Barari Villa – Interior Joinery | C3: Private Villa Client | D3: Syed Hussain | E3: Al Barari, Dubai | F3: High | G3: 46266 | H3: 46336 | I3: 7 | J3: 5 | K3: 6 | L3: 4 | M3: 25 | N3: 5 | O3: 3 | P3: 4 | Q3: Planned
A4: PRJ002 | B4: Palm Jumeirah Hotel – Joinery & MEP Fit-out | C4: Hospitality Group | D4: Tyson | E4: Palm Jumeirah, Dubai | F4: High | G4: 46280 | H4: 46376 | I4: 10 | J4: 7 | K4: 8 | L4: 5 | M4: 40 | N4: 7 | O4: 5 | P4: 6 | Q4: Planned
A5: PRJ003 | B5: Business Bay Office – Joinery & Manufacturing | C5: Corporate Client | D5: Syed Hussain | E5: Business Bay, Dubai | F5: Medium | G5: 46296 | H5: 46351 | I5: 5 | J5: 4 | K5: 5 | L5: 3 | M5: 18 | N5: 4 | O5: 3 | P5: 3 | Q5: Planned
A6: PRJ004 | B6: Dubai Mall Retail Store – Fast-track Fit-out | C6: Retail Brand | D6: Vinay | E6: Downtown Dubai | F6: Urgent | G6: 46285 | H6: 46320 | I6: 3 | J6: 2 | K6: 3 | L6: 2 | M6: 14 | N6: 3 | O6: 2 | P6: 2 | Q6: Planned
A7: PRJ005 | B7: Sharjah Mosque – Furniture Manufacturing | C7: Government / Waqf | D7: Tyson | E7: Sharjah | F7: Medium | G7: 46300 | H7: 46361 | I7: 6 | J7: 5 | K7: 6 | L7: 4 | M7: 22 | N7: 5 | O7: 4 | P7: 5 | Q7: Planned
A8: PRJ006 | B8: Dubai Marina Yacht – Interior Joinery | C8: Private Owner | D8: Syed Hussain | E8: Dubai Marina | F8: High | G8: 46307 | H8: 46386 | I8: 8 | J8: 6 | K8: 7 | L8: 5 | M8: 30 | N8: 6 | O8: 4 | P8: 5 | Q8: Planned
A9: PRJ007 | B9: ABC RENOVATION PROJECT | C9: Private Owner | D9: Syed Hussain | E9: Palm Jumeirah, Dubai | F9: High | G9: ='Expected Output'!B35 -> 01-Sep-2026 | H9: ='Expected Output'!D36 -> 0 | I9: ='Expected Output'!D6 -> 5 | J9: ='Expected Output'!D9 -> 5 | K9: ='Expected Output'!D11 -> 5 | L9: ='Expected Output'!D13 -> 3 | M9: ='Expected Output'!D15 -> 48 | N9: ='Expected Output'!D20 -> 2 | O9: ='Expected Output'!D23 -> 3 | P9: ='Expected Output'!D25 -> 3 | Q9: Planned

Sheet Calendar Rules
A1: Category | B1: Work Days | C1: Weekly Off Day(s) | D1: Standard Daily Hours | E1: Overtime Rule | F1: Notes
A2: White Collar | B2: Monday – Friday | C2: Saturday, Sunday | D2: 8 | E2: Not Applicable | F2: Design, Planning, Procurement, Sourcing, QA Engineer, Logistics Coordinator and other management/engineering roles.
A3: Blue Collar | B3: Monday – Saturday | C3: Sunday | D3: 8 | E3: Applicable beyond 8 hrs/day or on approved additional working days (incl. Sunday if approved) | F3: Manufacturing, QC Inspector, Packing, Dispatch/Driver and other operational/production floor roles.
A4: Public Holiday | B4: As per UAE official calendar | C4: - | D4: - | E4: Applicable if worked, per labor law | F4: Candidate's system should allow admin to mark specific dates as Public Holidays affecting all categories.

Sheet Expected Output
A1: Project : PRJ007 - ABC RENOVATION PROJECT, Production Manpower Plan (Sample Expected Output)
B3: Project : PRJ007 - ABC RENOVATION PROJECT, Production Manpower Plan (Sample Expected Output) | C3: Resource | D3: Duration | E3: Start | F3: End | G3: Sep 2026 | AK3: Oct 2026
A4: Ref | B4: Tasks | C4: Role & Employee | D4: Days | E4: Date | F4: Date | G4: 1 | H4: 2 | I4: 3 | J4: 4 | K4: 5 | L4: 6 | M4: 7 | N4: 8 | O4: 9 | P4: 10 | Q4: 11 | R4: 12 | S4: 13 | T4: 14 | U4: 15 | V4: 16 | W4: 17 | X4: 18 | Y4: 19 | Z4: 20 | AA4: 21 | AB4: 22 | AC4: 23 | AD4: 24 | AE4: 25 | AF4: 26 | AG4: 27 | AH4: 28 | AI4: 29 | AJ4: 30 | AK4: 1 | AL4: 2 | AM4: 3 | AN4: 4 | AO4: 5 | AP4: 6 | AQ4: 7 | AR4: 8 | AS4: 9 | AT4: 10 | AU4: 11 | AV4: 12 | AW4: 13 | AX4: 14 | AY4: 15 | AZ4: 16 | BA4: 17 | BB4: 18 | BC4: 19 | BD4: 20 | BE4: 21 | BF4: 22 | BG4: 23 | BH4: 24 | BI4: 25 | BJ4: 26 | BK4: 27 | BL4: 28 | BM4: 29 | BN4: 30 | BO4: 31
G5: T | H5: W | I5: T | J5: F | K5: SA | L5: SU | M5: M | N5: T | O5: W | P5: T | Q5: F | R5: SA | S5: SU | T5: M | U5: T | V5: W | W5: T | X5: F | Y5: SA | Z5: SU | AA5: M | AB5: T | AC5: W | AD5: T | AE5: F | AF5: SA | AG5: SU | AH5: M | AI5: T | AJ5: W | AK5: T | AL5: F | AM5: SA | AN5: SU | AO5: M | AP5: T | AQ5: W | AR5: T | AS5: F | AT5: SA | AU5: SU | AV5: M | AW5: T | AX5: W | AY5: T | AZ5: F | BA5: SA | BB5: SU | BC5: M | BD5: T | BE5: W | BF5: T | BG5: F | BH5: SA | BI5: SU | BJ5: M | BK5: T | BL5: W | BM5: T | BN5: F | BO5: SA
B6: Stage 1: Design | C6: Design Team (White Collar) | D6: =SUM(D7:D8) -> 5 | E6: 01-Sep-2026 | F6: 04-Sep-2026 | G6: Design
A7: 1 | B7: Concept design & drawings | C7: Design Engineer - Ahmed Sharma (EMP002) | D7: 3 | E7: 01-Sep-2026 | F7: 03-Sep-2026 | G7: 1 | H7: 2 | I7: 3
A8: 2 | B8: CAD detailing & shop drawings | C8: CAD Draftsman - Ahmed Iyer (EMP005) | D8: 2 | E8: 03-Sep-2026 | F8: 04-Sep-2026 | I8: 4 | J8: 5
B9: Stage 2: Planning | C9: Planning Team (White Collar) | D9: =SUM(D10) -> 5 | E9: 46272 | F9: 46276 | M9: Planning
A10: 3 | B10: Production planning & scheduling | C10: Project Planner - Ahmed Nair (EMP009) | D10: 5 | E10: 07-Sep-2026 | F10: 46276 | M10: 6 | N10: 7 | O10: 8 | P10: 9 | Q10: 10
B11: Stage 3: Procurement | C11: Procurement Team (White Collar) | D11: =SUM(D12) -> 5 | E11: 14-Sep-2026 | F11: 18-Sep-2026 | T11: Procurement
A12: 4 | B12: Material & BOQ procurement | C12: Procurement Officer - Ahmed Baig (EMP012) | D12: 5 | E12: 13-Sep-2026 | F12: 18-Sep-2026 | T12: 11 | U12: 12 | V12: 13 | W12: 14 | X12: 15
B13: Stage 4: Sourcing | C13: Sourcing Team (White Collar) | D13: 3 | E13: 21-Sep-2026 | F13: 24-Sep-2026 | AA13: Sourcing
A14: 5 | B14: Vendor & supplier sourcing | C14: Vendor Dev. Exec. - Ahmed Rao (EMP015) | D14: 3 | E14: 21-Sep-2026 | F14: 24-Sep-2026 | AA14: 16 | AB14: 17 | AC14: 18
B15: Stage 5: Manufacturing | C15: Production Floor (Blue Collar) | D15: =SUM(D16:D19) -> 48 | E15: 19-Sep-2026 | F15: 23-Sep-2026 | AD15: Manufacturing
A16: 6 | B16: Carpentry & assembly | C16: Carpenter - Rahul Sharma (EMP022) | D16: 15 | E16: 24-Sep-2026 | F16: 46305 | AD16: 19 | AE16: 20 | AF16: 21 | AH16: 22 | AI16: 23 | AJ16: 24 | AK16: 25 | AL16: 26 | AM16: 27 | AO16: 28 | AP16: 29 | AQ16: 30 | AR16: 31 | AS16: 32 | AT16: 33
A17: 7 | B17: CNC cutting & edge banding | C17: Machine Operator - Rahul Hussain (EMP026) | D17: 10 | E17: 24-Sep-2026 | F17: 46300 | AD17: 19 | AE17: 20 | AF17: 21 | AH17: 22 | AI17: 23 | AJ17: 24 | AK17: 25 | AL17: 26 | AM17: 27 | AO17: 28
A18: 8 | B18: Welding & metal fabrication | C18: Welder/Fabricator - Rahul Siddiqui (EMP030) | D18: 11 | E18: 06-Oct-2026 | F18: 18-Oct-2026 | AP18: 29 | AQ18: 30 | AR18: 31 | AS18: 32 | AT18: 33 | AV18: 34 | AW18: 35 | AX18: 36 | AY18: 37 | AZ18: 38 | BA18: 39
A19: 9 | B19: Finishing & polishing | C19: Finishing Technician - Rahul Menon (EMP033) | D19: 12 | E19: 11-Oct-2026 | F19: 23-Oct-2026 | AV19: 34 | AW19: 35 | AX19: 36 | AY19: 37 | AZ19: 38 | BA19: 39 | BC19: 40 | BD19: 41 | BE19: 42 | BF19: 43 | BG19: 44 | BH19: 45
B20: Stage 6: Quality Control | C20: QA/QC Team (Mixed) | D20: =SUM(D21:D22) -> 2 | E20: 24-Oct-2026 | F20: 26-Oct-2026 | BH20: QA/QC
A21: 10 | B21: In-line quality inspection | C21: QC Inspector - Suresh Sharma (EMP042) | D21: 1 | E21: 24-Oct-2026 | F21: 24-Oct-2026 | BH21: 45
A22: 11 | B22: Final QA sign-off | C22: QA Engineer - Rahul Chaudhry (EMP040) | D22: 1 | E22: 26-Oct-2026 | F22: 26-Oct-2026 | BJ22: 46
B23: Stage 7: Packing | C23: Packing Team (Blue Collar) | D23: =SUM(D24) -> 3 | E23: 26-Oct-2026 | F23: 28-Oct-2026 | BJ23: Packing
A24: 12 | B24: Packing & crating | C24: Packing Helper - Suresh Hussain (EMP046) | D24: 3 | E24: 26-Oct-2026 | F24: 28-Oct-2026 | BJ24: 46 | BK24: 47 | BL24: 48
B25: Stage 8: Shipping | C25: Logistics Team (Mixed) | D25: =SUM(D26:D27) -> 3 | E25: 29-Oct-2026 | F25: 30-Oct-2026 | BM25: Shipping
A26: 13 | B26: Dispatch coordination | C26: Logistics Coordinator - Suresh Nair (EMP049) | D26: 1 | E26: 29-Oct-2026 | F26: 29-Oct-2026 | BM26: 49
A27: 14 | B27: Loading & transport | C27: Driver - Suresh Baig (EMP052) | D27: 2 | E27: 30-Oct-2026 | F27: 46326 | BN27: 50 | BO27: 51
B28: Total (Resource-Days, sum of all employees' individual days)
A30: Report Summary
A31: PROJECT NAME | B31: PRJ007 - ABC RENOVATION PROJECT
A32: PROJECT MANAGER | B32: Syed Hussain
A33: Total Man Power Days | B33: 74 | C33: Days
A34: Actual Working Days | B34: 51 | C34: Days
A35: Project Start Date | B35: 01-Sep-2026
A36: Project Expected Completion Date | B36: 46326
A40: Manufacturing Stages
A41: SNO | B41: Stage Name | C41: Days
A42: 1 | B42: Design | C42: =D6 -> 5
A43: 2 | B43: Planning | C43: =D9 -> 5
A44: 3 | B44: Procurement | C44: =D11 -> 5
A45: 4 | B45: Sourcing | C45: =D13 -> 3
...
